Workbook

Sheet 테마비교
A1: 지면 | F1: whiteRedNo | I1: blackGoldNo | L1: magazine | O1: mcnal | R1: 합계
A2: TAG ID | B2: 사이즈 | C2: 구분 | D2: 매체 | E2: 테마 수 | F2: 노출수 | G2: 클릭수 | H2: 클릭률 | I2: 노출수 | J2: 클릭수 | K2: 클릭률 | L2: 노출수 | M2: 클릭수 | N2: 클릭률 | O2: 노출수 | P2: 클릭수 | Q2: 클릭률 | R2: 노출수 | S2: 클릭수 | T2: 클릭률
A3: web_theqoo.net_banner_1_N_v2 | B3: 728_90 | C3: web | D3: theqoo.net | E3: =COUNT(F3,I3,L3,O3) -> 4 | F3: 38396 | G3: 12 | H3: =IF(F3="","",G3/F3) -> 0.00031253256 | I3: 30446 | J3: 2 | K3: =IF(I3="","",J3/I3) -> 6.5690074e-05 | L3: 30220 | M3: 6 | N3: =IF(L3="","",M3/L3) -> 0.00019854401 | O3: 6382 | P3: 1 | Q3: =IF(O3="","",P3/O3) -> 0.00015669069 | R3: =SUM(F3,I3,L3,O3) -> 105444 | S3: =SUM(G3,J3,M3,P3) -> 21 | T3: =IF(R3=0,"",S3/R3) -> 0.00019915785
A4: web_theqoo.net_banner_1_N_v2 | B4: 160_600 | C4: web | D4: theqoo.net | E4: =COUNT(F4,I4,L4,O4) -> 4 | F4: 33966 | G4: 10 | H4: =IF(F4="","",G4/F4) -> 0.00029441206 | I4: 28256 | J4: 10 | K4: =IF(I4="","",J4/I4) -> 0.00035390713 | L4: 28494 | M4: 12 | N4: =IF(L4="","",M4/L4) -> 0.00042114129 | O4: 4751 | P4: 1 | Q4: =IF(O4="","",P4/O4) -> 0.000210482 | R4: =SUM(F4,I4,L4,O4) -> 95467 | S4: =SUM(G4,J4,M4,P4) -> 33 | T4: =IF(R4=0,"",S4/R4) -> 0.00034566918
A5: web_theqoo.net_banner_1_N_v2 | B5: 120_600 | C5: web | D5: theqoo.net | E5: =COUNT(F5,I5,L5,O5) -> 4 | F5: 31128 | G5: 8 | H5: =IF(F5="","",G5/F5) -> 0.00025700334 | I5: 25665 | J5: 7 | K5: =IF(I5="","",J5/I5) -> 0.00027274498 | L5: 25782 | M5: 19 | N5: =IF(L5="","",M5/L5) -> 0.00073694826 | O5: 4131 | P5: 3 | Q5: =IF(O5="","",P5/O5) -> 0.00072621641 | R5: =SUM(F5,I5,L5,O5) -> 86706 | S5: =SUM(G5,J5,M5,P5) -> 37 | T5: =IF(R5=0,"",S5/R5) -> 0.00042672941
A6: mob_imbc.com_banner_5_N_v2 | B6: 320_50 | C6: mob | D6: imbc.com | E6: =COUNT(F6,I6,L6,O6) -> 4 | F6: 29697 | G6: 0 | H6: =IF(F6="","",G6/F6) -> 0 | I6: 24365 | J6: 0 | K6: =IF(I6="","",J6/I6) -> 0 | L6: 24107 | M6: 0 | N6: =IF(L6="","",M6/L6) -> 0 | O6: 8360 | P6: 0 | Q6: =IF(O6="","",P6/O6) -> 0 | R6: =SUM(F6,I6,L6,O6) -> 86529 | S6: =SUM(G6,J6,M6,P6) -> 0 | T6: =IF(R6=0,"",S6/R6) -> 0
A7: web_daum.net_banner_3_N_v2 | B7: 300_250 | C7: web | D7: daum.net | E7: =COUNT(F7,I7,L7,O7) -> 4 | F7: 26827 | G7: 0 | H7: =IF(F7="","",G7/F7) -> 0 | I7: 22559 | J7: 1 | K7: =IF(I7="","",J7/I7) -> 4.4328206e-05 | L7: 22193 | M7: 0 | N7: =IF(L7="","",M7/L7) -> 0 | O7: 5368 | P7: 0 | Q7: =IF(O7="","",P7/O7) -> 0 | R7: =SUM(F7,I7,L7,O7) -> 76947 | S7: =SUM(G7,J7,M7,P7) -> 1 | T7: =IF(R7=0,"",S7/R7) -> 1.2995958e-05
A8: web_daum.net_banner_3_N_v2 | B8: 728_90 | C8: web | D8: daum.net | E8: =COUNT(F8,I8,L8,O8) -> 4 | F8: 23222 | G8: 2 | H8: =IF(F8="","",G8/F8) -> 8.6125226e-05 | I8: 23035 | J8: 0 | K8: =IF(I8="","",J8/I8) -> 0 | L8: 23346 | M8: 1 | N8: =IF(L8="","",M8/L8) -> 4.283389e-05 | O8: 5044 | P8: 0 | Q8: =IF(O8="","",P8/O8) -> 0 | R8: =SUM(F8,I8,L8,O8) -> 74647 | S8: =SUM(G8,J8,M8,P8) -> 3 | T8: =IF(R8=0,"",S8/R8) -> 4.0189157e-05
A9: web_cafe.daum.net_banner_3_N_v2 | B9: 728_90 | C9: web | D9: cafe.daum.net | E9: =COUNT(F9,I9,L9,O9) -> 4 | F9: 24841 | G9: 10 | H9: =IF(F9="","",G9/F9) -> 0.00040256028 | I9: 18155 | J9: 6 | K9: =IF(I9="","",J9/I9) -> 0.00033048747 | L9: 18211 | M9: 13 | N9: =IF(L9="","",M9/L9) -> 0.00071385426 | O9: 3698 | P9: 1 | Q9: =IF(O9="","",P9/O9) -> 0.00027041644 | R9: =SUM(F9,I9,L9,O9) -> 64905 | S9: =SUM(G9,J9,M9,P9) -> 30 | T9: =IF(R9=0,"",S9/R9) -> 0.00046221401
A10: web_v.daum.net_banner_1_N_v2 | B10: 300_250 | C10: web | D10: v.daum.net | E10: =COUNT(F10,I10,L10,O10) -> 4 | F10: 22361 | G10: 11 | H10: =IF(F10="","",G10/F10) -> 0.00049192791 | I10: 16869 | J10: 23 | K10: =IF(I10="","",J10/I10) -> 0.0013634477 | L10: 16978 | M10: 37 | N10: =IF(L10="","",M10/L10) -> 0.0021792908 | O10: 2471 | P10: 2 | Q10: =IF(O10="","",P10/O10) -> 0.00080938891 | R10: =SUM(F10,I10,L10,O10) -> 58679 | S10: =SUM(G10,J10,M10,P10) -> 73 | T10: =IF(R10=0,"",S10/R10) -> 0.0012440566
A11: web_wisetoto.com_banner_3_N_v2 | B11: 728_90 | C11: web | D11: wisetoto.com | E11: =COUNT(F11,I11,L11,O11) -> 4 | F11: 11190 | G11: 4 | H11: =IF(F11="","",G11/F11) -> 0.00035746202 | I11: 8024 | J11: 0 | K11: =IF(I11="","",J11/I11) -> 0 | L11: 8164 | M11: 2 | N11: =IF(L11="","",M11/L11) -> 0.00024497795 | O11: 2645 | P11: 0 | Q11: =IF(O11="","",P11/O11) -> 0 | R11: =SUM(F11,I11,L11,O11) -> 30023 | S11: =SUM(G11,J11,M11,P11) -> 6 | T11: =IF(R11=0,"",S11/R11) -> 0.00019984678
A12: web_inven.co.kr_banner_0_N_v2 | B12: 200_200 | C12: web | D12: inven.co.kr | E12: =COUNT(F12,I12,L12,O12) -> 4 | F12: 9030 | G12: 1 | H12: =IF(F12="","",G12/F12) -> 0.00011074197 | I12: 7190 | J12: 1 | K12: =IF(I12="","",J12/I12) -> 0.00013908206 | L12: 7201 | M12: 1 | N12: =IF(L12="","",M12/L12) -> 0.0001388696 | O12: 2163 | P12: 0 | Q12: =IF(O12="","",P12/O12) -> 0 | R12: =SUM(F12,I12,L12,O12) -> 25584 | S12: =SUM(G12,J12,M12,P12) -> 3 | T12: =IF(R12=0,"",S12/R12) -> 0.00011726079
A13: web_theqoo.net_banner_3_N_v2 | B13: 160_600 | C13: web | D13: theqoo.net | E13: =COUNT(F13,I13,L13,O13) -> 4 | F13: 8458 | G13: 0 | H13: =IF(F13="","",G13/F13) -> 0 | I13: 7062 | J13: 0 | K13: =IF(I13="","",J13/I13) -> 0 | L13: 7119 | M13: 0 | N13: =IF(L13="","",M13/L13) -> 0 | O13: 1250 | P13: 0 | Q13: =IF(O13="","",P13/O13) -> 0 | R13: =SUM(F13,I13,L13,O13) -> 23889 | S13: =SUM(G13,J13,M13,P13) -> 0 | T13: =IF(R13=0,"",S13/R13) -> 0
A14: web_nate.com_banner_1_N_v2 | B14: 320_100 | C14: web | D14: nate.com | E14: =COUNT(F14,I14,L14,O14) -> 4 | F14: 8412 | G14: 1 | H14: =IF(F14="","",G14/F14) -> 0.00011887779 | I14: 6600 | J14: 1 | K14: =IF(I14="","",J14/I14) -> 0.00015151515 | L14: 6698 | M14: 3 | N14: =IF(L14="","",M14/L14) -> 0.00044789489 | O14: 1028 | P14: 1 | Q14: =IF(O14="","",P14/O14) -> 0.00097276265 | R14: =SUM(F14,I14,L14,O14) -> 22738 | S14: =SUM(G14,J14,M14,P14) -> 6 | T14: =IF(R14=0,"",S14/R14) -> 0.00026387545
... A119: mob_inven.co.kr_banner_0_N_v2 | B119: 320_50 | C119: mob | D119: inven.co.kr | E119: =COUNT(F119,I119,L119,O119) -> 4 | F119: 690 | G119: 1 | H119: =IF(F119="","",G119/F119) -> 0.0014492754 | I119: 530 | J119: 1 | K119: =IF(I119="","",J119/I119) -> 0.0018867925 | L119: 511 | M119: 0 | N119: =IF(L119="","",M119/L119) -> 0 | O119: 138 | P119: 0 | Q119: =IF(O119="","",P119/O119) -> 0 | R119: =SUM(F119,I119,L119,O119) -> 1869 | S119: =SUM(G119,J119,M119,P119) -> 2 | T119: =IF(R119=0,"",S119/R119) -> 0.001070091
A120: web_82cook.com_banner_1_N_v2 | B120: 468_60 | C120: web | D120: 82cook.com | E120: =COUNT(F120,I120,L120,O120) -> 2 | H120: =IF(F120="","",G120/F120) | K120: =IF(I120="","",J120/I120) | L120: 1634 | M120: 0 | N120: =IF(L120="","",M120/L120) -> 0 | O120: 225 | P120: 0 | Q120: =IF(O120="","",P120/O120) -> 0 | R120: =SUM(F120,I120,L120,O120) -> 1859 | S120: =SUM(G120,J120,M120,P120) -> 0 | T120: =IF(R120=0,"",S120/R120) -> 0
A121: web_dmitory.com_banner_3_N_v2 | B121: 160_600 | C121: web | D121: dmitory.com | E121: =COUNT(F121,I121,L121,O121) -> 4 | F121: 605 | G121: 0 | H121: =IF(F121="","",G121/F121) -> 0 | I121: 527 | J121: 0 | K121: =IF(I121="","",J121/I121) -> 0 | L121: 545 | M121: 0 | N121: =IF(L121="","",M121/L121) -> 0 | O121: 136 | P121: 0 | Q121: =IF(O121="","",P121/O121) -> 0 | R121: =SUM(F121,I121,L121,O121) -> 1813 | S121: =SUM(G121,J121,M121,P121) -> 0 | T121: =IF(R121=0,"",S121/R121) -> 0
A122: mob_damoang.net_banner_3_N_v2 | B122: 320_50 | C122: mob | D122: damoang.net | E122: =COUNT(F122,I122,L122,O122) -> 4 | F122: 589 | G122: 0 | H122: =IF(F122="","",G122/F122) -> 0 | I122: 535 | J122: 0 | K122: =IF(I122="","",J122/I122) -> 0 | L122: 524 | M122: 0 | N122: =IF(L122="","",M122/L122) -> 0 | O122: 163 | P122: 0 | Q122: =IF(O122="","",P122/O122) -> 0 | R122: =SUM(F122,I122,L122,O122) -> 1811 | S122: =SUM(G122,J122,M122,P122) -> 0 | T122: =IF(R122=0,"",S122/R122) -> 0
A123: web_v.daum.net_banner_3_N_v2 | B123: 300_250 | C123: web | D123: v.daum.net | E123: =COUNT(F123,I123,L123,O123) -> 4 | F123: 707 | G123: 0 | H123: =IF(F123="","",G123/F123) -> 0 | I123: 498 | J123: 0 | K123: =IF(I123="","",J123/I123) -> 0 | L123: 516 | M123: 3 | N123: =IF(L123="","",M123/L123) -> 0.0058139535 | O123: 89 | P123: 0 | Q123: =IF(O123="","",P123/O123) -> 0 | R123: =SUM(F123,I123,L123,O123) -> 1810 | S123: =SUM(G123,J123,M123,P123) -> 3 | T123: =IF(R123=0,"",S123/R123) -> 0.0016574586
A124: web_dvdprime.com_banner_6_N_v2 | B124: 300_600 | C124: web | D124: dvdprime.com | E124: =COUNT(F124,I124,L124,O124) -> 4 | F124: 621 | G124: 0 | H124: =IF(F124="","",G124/F124) -> 0 | I124: 524 | J124: 1 | K124: =IF(I124="","",J124/I124) -> 0.0019083969 | L124: 485 | M124: 3 | N124: =IF(L124="","",M124/L124) -> 0.006185567 | O124: 128 | P124: 0 | Q124: =IF(O124="","",P124/O124) -> 0 | R124: =SUM(F124,I124,L124,O124) -> 1758 | S124: =SUM(G124,J124,M124,P124) -> 4 | T124: =IF(R124=0,"",S124/R124) -> 0.0022753129
A125: web_dogdrip.net_banner_3_N_v2 | B125: 160_600 | C125: web | D125: dogdrip.net | E125: =COUNT(F125,I125,L125,O125) -> 4 | F125: 642 | G125: 0 | H125: =IF(F125="","",G125/F125) -> 0 | I125: 510 | J125: 1 | K125: =IF(I125="","",J125/I125) -> 0.0019607843 | L125: 496 | M125: 0 | N125: =IF(L125="","",M125/L125) -> 0 | O125: 93 | P125: 0 | Q125: =IF(O125="","",P125/O125) -> 0 | R125: =SUM(F125,I125,L125,O125) -> 1741 | S125: =SUM(G125,J125,M125,P125) -> 1 | T125: =IF(R125=0,"",S125/R125) -> 0.00057438254
A126: web_dogdrip.net_banner_3_N_v2 | B126: 120_600 | C126: web | D126: dogdrip.net | E126: =COUNT(F126,I126,L126,O126) -> 4 | F126: 662 | G126: 0 | H126: =IF(F126="","",G126/F126) -> 0 | I126: 495 | J126: 0 | K126: =IF(I126="","",J126/I126) -> 0 | L126: 479 | M126: 1 | N126: =IF(L126="","",M126/L126) -> 0.0020876827 | O126: 93 | P126: 0 | Q126: =IF(O126="","",P126/O126) -> 0 | R126: =SUM(F126,I126,L126,O126) -> 1729 | S126: =SUM(G126,J126,M126,P126) -> 1 | T126: =IF(R126=0,"",S126/R126) -> 0.000578369
A127: mob_inven.co.kr_banner_0_N_v2 | B127: 300_50 | C127: mob | D127: inven.co.kr | E127: =COUNT(F127,I127,L127,O127) -> 4 | F127: 597 | G127: 0 | H127: =IF(F127="","",G127/F127) -> 0 | I127: 458 | J127: 0 | K127: =IF(I127="","",J127/I127) -> 0 | L127: 539 | M127: 0 | N127: =IF(L127="","",M127/L127) -> 0 | O127: 116 | P127: 0 | Q127: =IF(O127="","",P127/O127) -> 0 | R127: =SUM(F127,I127,L127,O127) -> 1710 | S127: =SUM(G127,J127,M127,P127) -> 0 | T127: =IF(R127=0,"",S127/R127) -> 0
A128: mob_damoang.net_banner_3_N_v2 | B128: 320_100 | C128: mob | D128: damoang.net | E128: =COUNT(F128,I128,L128,O128) -> 4 | F128: 570 | G128: 0 | H128: =IF(F128="","",G128/F128) -> 0 | I128: 483 | J128: 2 | K128: =IF(I128="","",J128/I128) -> 0.0041407867 | L128: 482 | M128: 0 | N128: =IF(L128="","",M128/L128) -> 0 | O128: 174 | P128: 0 | Q128: =IF(O128="","",P128/O128) -> 0 | R128: =SUM(F128,I128,L128,O128) -> 1709 | S128: =SUM(G128,J128,M128,P128) -> 2 | T128: =IF(R128=0,"",S128/R128) -> 0.001170275
A129: web_itssa.co.kr_banner_1_N_v2 | B129: 200_200 | C129: web | D129: itssa.co.kr | E129: =COUNT(F129,I129,L129,O129) -> 4 | F129: 611 | G129: 2 | H129: =IF(F129="","",G129/F129) -> 0.0032733224 | I129: 473 | J129: 0 | K129: =IF(I129="","",J129/I129) -> 0 | L129: 497 | M129: 0 | N129: =IF(L129="","",M129/L129) -> 0 | O129: 109 | P129: 0 | Q129: =IF(O129="","",P129/O129) -> 0 | R129: =SUM(F129,I129,L129,O129) -> 1690 | S129: =SUM(G129,J129,M129,P129) -> 2 | T129: =IF(R129=0,"",S129/R129) -> 0.001183432
A130: web_asiae.co.kr_banner_0_N_v2 | B130: 300_250 | C130: web | D130: asiae.co.kr | E130: =COUNT(F130,I130,L130,O130) -> 4 | F130: 583 | G130: 0 | H130: =IF(F130="","",G130/F130) -> 0 | I130: 532 | J130: 2 | K130: =IF(I130="","",J130/I130) -> 0.0037593985 | L130: 498 | M130: 0 | N130: =IF(L130="","",M130/L130) -> 0 | O130: 69 | P130: 1 | Q130: =IF(O130="","",P130/O130) -> 0.014492754 | R130: =SUM(F130,I130,L130,O130) -> 1682 | S130: =SUM(G130,J130,M130,P130) -> 3 | T130: =IF(R130=0,"",S130/R130) -> 0.001783591
A131: mob_ppomppu.co.kr_banner_1_N_v2 | B131: 336_280 | C131: mob | D131: ppomppu.co.kr | E131: =COUNT(F131,I131,L131,O131) -> 4 | F131: 574 | G131: 2 | H131: =IF(F131="","",G131/F131) -> 0.0034843206 | I131: 477 | J131: 1 | K131: =IF(I131="","",J131/I131) -> 0.0020964361 | L131: 518 | M131: 0 | N131: =IF(L131="","",M131/L131) -> 0 | O131: 106 | P131: 0 | Q131: =IF(O131="","",P131/O131) -> 0 | R131: =SUM(F131,I131,L131,O131) -> 1675 | S131: =SUM(G131,J131,M131,P131) -> 3 | T131: =IF(R131=0,"",S131/R131) -> 0.0017910448
A132: mob_khan.co.kr_banner_0_N_v2 | B132: 320_100 | C132: mob | D132: khan.co.kr | E132: =COUNT(F132,I132,L132,O132) -> 4 | F132: 611 | G132: 0 | H132: =IF(F132="","",G132/F132) -> 0 | I132: 447 | J132: 0 | K132: =IF(I132="","",J132/I132) -> 0 | L132: 483 | M132: 0 | N132: =IF(L132="","",M132/L132) -> 0 | O132: 115 | P132: 0 | Q132: =IF(O132="","",P132/O132) -> 0 | R132: =SUM(F132,I132,L132,O132) -> 1656 | S132: =SUM(G132,J132,M132,P132) -> 0 | T132: =IF(R132=0,"",S132/R132) -> 0
... A249: web_meaegi.com_banner_1_N_v2 | B249: 728_90 | C249: web | D249: meaegi.com | E249: =COUNT(F249,I249,L249,O249) -> 4 | F249: 209 | G249: 0 | H249: =IF(F249="","",G249/F249) -> 0 | I249: 117 | J249: 0 | K249: =IF(I249="","",J249/I249) -> 0 | L249: 130 | M249: 0 | N249: =IF(L249="","",M249/L249) -> 0 | O249: 75 | P249: 0 | Q249: =IF(O249="","",P249/O249) -> 0 | R249: =SUM(F249,I249,L249,O249) -> 531 | S249: =SUM(G249,J249,M249,P249) -> 0 | T249: =IF(R249=0,"",S249/R249) -> 0
A250: web_onlinealarmkur.com_banner_6_N_v2 | B250: 300_600 | C250: web | D250: onlinealarmkur.com | E250: =COUNT(F250,I250,L250,O250) -> 3 | F250: 176 | G250: 0 | H250: =IF(F250="","",G250/F250) -> 0 | I250: 172 | J250: 0 | K250: =IF(I250="","",J250/I250) -> 0 | L250: 163 | M250: 0 | N250: =IF(L250="","",M250/L250) -> 0 | Q250: =IF(O250="","",P250/O250) | R250: =SUM(F250,I250,L250,O250) -> 511 | S250: =SUM(G250,J250,M250,P250) -> 0 | T250: =IF(R250=0,"",S250/R250) -> 0
A251: web_ytn.co.kr_banner_0_N_v2 | B251: 300_250 | C251: web | D251: ytn.co.kr | E251: =COUNT(F251,I251,L251,O251) -> 4 | F251: 173 | G251: 0 | H251: =IF(F251="","",G251/F251) -> 0 | I251: 156 | J251: 1 | K251: =IF(I251="","",J251/I251) -> 0.0064102564 | L251: 152 | M251: 0 | N251: =IF(L251="","",M251/L251) -> 0 | O251: 25 | P251: 0 | Q251: =IF(O251="","",P251/O251) -> 0 | R251: =SUM(F251,I251,L251,O251) -> 506 | S251: =SUM(G251,J251,M251,P251) -> 1 | T251: =IF(R251=0,"",S251/R251) -> 0.0019762846
A252: web_comcbt.com_banner_1_N_v2 | B252: 728_90 | C252: web | D252: comcbt.com | E252: =COUNT(F252,I252,L252,O252) -> 4 | F252: 157 | G252: 0 | H252: =IF(F252="","",G252/F252) -> 0 | I252: 152 | J252: 0 | K252: =IF(I252="","",J252/I252) -> 0 | L252: 121 | M252: 0 | N252: =IF(L252="","",M252/L252) -> 0 | O252: 75 | P252: 0 | Q252: =IF(O252="","",P252/O252) -> 0 | R252: =SUM(F252,I252,L252,O252) -> 505 | S252: =SUM(G252,J252,M252,P252) -> 0 | T252: =IF(R252=0,"",S252/R252) -> 0
A253: web_ppomppu.co.kr_banner_1_N_v2 | B253: 250_250 | C253: web | D253: ppomppu.co.kr | E253: =COUNT(F253,I253,L253,O253) -> 4 | F253: 165 | G253: 0 | H253: =IF(F253="","",G253/F253) -> 0 | I253: 157 | J253: 0 | K253: =IF(I253="","",J253/I253) -> 0 | L253: 152 | M253: 0 | N253: =IF(L253="","",M253/L253) -> 0 | O253: 31 | P253: 0 | Q253: =IF(O253="","",P253/O253) -> 0 | R253: =SUM(F253,I253,L253,O253) -> 505 | S253: =SUM(G253,J253,M253,P253) -> 0 | T253: =IF(R253=0,"",S253/R253) -> 0
A254: mob_hankyung.com_banner_3_N_v2 | B254: 250_250 | C254: mob | D254: hankyung.com | E254: =COUNT(F254,I254,L254,O254) -> 4 | F254: 169 | G254: 0 | H254: =IF(F254="","",G254/F254) -> 0 | I254: 131 | J254: 0 | K254: =IF(I254="","",J254/I254) -> 0 | L254: 161 | M254: 0 | N254: =IF(L254="","",M254/L254) -> 0 | O254: 40 | P254: 0 | Q254: =IF(O254="","",P254/O254) -> 0 | R254: =SUM(F254,I254,L254,O254) -> 501 | S254: =SUM(G254,J254,M254,P254) -> 0 | T254: =IF(R254=0,"",S254/R254) -> 0
A255: web_sports.khan.co.kr_banner_0_N_v2 | B255: 300_250 | C255: web | D255: sports.khan.co.kr | E255: =COUNT(F255,I255,L255,O255) -> 4 | F255: 178 | G255: 0 | H255: =IF(F255="","",G255/F255) -> 0 | I255: 136 | J255: 0 | K255: =IF(I255="","",J255/I255) -> 0 | L255: 141 | M255: 0 | N255: =IF(L255="","",M255/L255) -> 0 | O255: 44 | P255: 0 | Q255: =IF(O255="","",P255/O255) -> 0 | R255: =SUM(F255,I255,L255,O255) -> 499 | S255: =SUM(G255,J255,M255,P255) -> 0 | T255: =IF(R255=0,"",S255/R255) -> 0
A256: web_cafe.daum.net_banner_3_N_v2 | B256: 970_250 | C256: web | D256: cafe.daum.net | E256: =COUNT(F256,I256,L256,O256) -> 4 | F256: 172 | G256: 0 | H256: =IF(F256="","",G256/F256) -> 0 | I256: 161 | J256: 0 | K256: =IF(I256="","",J256/I256) -> 0 | L256: 143 | M256: 0 | N256: =IF(L256="","",M256/L256) -> 0 | O256: 21 | P256: 0 | Q256: =IF(O256="","",P256/O256) -> 0 | R256: =SUM(F256,I256,L256,O256) -> 497 | S256: =SUM(G256,J256,M256,P256) -> 0 | T256: =IF(R256=0,"",S256/R256) -> 0
A257: web_cafe.daum.net_banner_3_N_v2 | B257: 300_250 | C257: web | D257: cafe.daum.net | E257: =COUNT(F257,I257,L257,O257) -> 4 | F257: 155 | G257: 0 | H257: =IF(F257="","",G257/F257) -> 0 | I257: 121 | J257: 0 | K257: =IF(I257="","",J257/I257) -> 0 | L257: 128 | M257: 0 | N257: =IF(L257="","",M257/L257) -> 0 | O257: 90 | P257: 0 | Q257: =IF(O257="","",P257/O257) -> 0 | R257: =SUM(F257,I257,L257,O257) -> 494 | S257: =SUM(G257,J257,M257,P257) -> 0 | T257: =IF(R257=0,"",S257/R257) -> 0
A258: web_lol.ps_banner_1_N_v2 | B258: 160_600 | C258: web | D258: lol.ps | E258: =COUNT(F258,I258,L258,O258) -> 4 | F258: 155 | G258: 1 | H258: =IF(F258="","",G258/F258) -> 0.0064516129 | I258: 135 | J258: 0 | K258: =IF(I258="","",J258/I258) -> 0 | L258: 118 | M258: 0 | N258: =IF(L258="","",M258/L258) -> 0 | O258: 80 | P258: 0 | Q258: =IF(O258="","",P258/O258) -> 0 | R258: =SUM(F258,I258,L258,O258) -> 488 | S258: =SUM(G258,J258,M258,P258) -> 1 | T258: =IF(R258=0,"",S258/R258) -> 0.0020491803
A259: web_mt.co.kr_banner_0_N_v2 | B259: 160_600 | C259: web | D259: mt.co.kr | E259: =COUNT(F259,I259,L259,O259) -> 4 | F259: 182 | G259: 0 | H259: =IF(F259="","",G259/F259) -> 0 | I259: 144 | J259: 0 | K259: =IF(I259="","",J259/I259) -> 0 | L259: 136 | M259: 0 | N259: =IF(L259="","",M259/L259) -> 0 | O259: 25 | P259: 0 | Q259: =IF(O259="","",P259/O259) -> 0 | R259: =SUM(F259,I259,L259,O259) -> 487 | S259: =SUM(G259,J259,M259,P259) -> 0 | T259: =IF(R259=0,"",S259/R259) -> 0
A260: web_onlinealarmkur.com_banner_1_N_v2 | B260: 728_90 | C260: web | D260: onlinealarmkur.com | E260: =COUNT(F260,I260,L260,O260) -> 3 | F260: 156 | G260: 0 | H260: =IF(F260="","",G260/F260) -> 0 | I260: 159 | J260: 0 | K260: =IF(I260="","",J260/I260) -> 0 | L260: 168 | M260: 0 | N260: =IF(L260="","",M260/L260) -> 0 | Q260: =IF(O260="","",P260/O260) | R260: =SUM(F260,I260,L260,O260) -> 483 | S260: =SUM(G260,J260,M260,P260) -> 0 | T260: =IF(R260=0,"",S260/R260) -> 0
...

Sheet 테마별요약
A1: 테마별 노출수 · 클릭수 · 클릭률 (2026-10-07)
A3: 1) 전체 (테마별 합계)
A4: 테마 | B4: 노출수 | C4: 클릭수 | D4: 클릭률 | E4: 지면 수(태그×사이즈)
A5: whiteRedNo | B5: =SUM(테마비교!F$3:F$2985) -> 566512 | C5: =SUM(테마비교!G$3:G$2985) -> 163 | D5: =IF(B5=0,"",C5/B5) -> 0.00028772559 | E5: =COUNT(테마비교!F$3:F$2985) -> 2428
A6: blackGoldNo | B6: =SUM(테마비교!I$3:I$2985) -> 456906 | C6: =SUM(테마비교!J$3:J$2985) -> 141 | D6: =IF(B6=0,"",C6/B6) -> 0.00030859739 | E6: =COUNT(테마비교!I$3:I$2985) -> 2277
A7: magazine | B7: =SUM(테마비교!L$3:L$2985) -> 459345 | C7: =SUM(테마비교!M$3:M$2985) -> 185 | D7: =IF(B7=0,"",C7/B7) -> 0.00040274739 | E7: =COUNT(테마비교!L$3:L$2985) -> 2317
A8: mcnal | B8: =SUM(테마비교!O$3:O$2985) -> 103525 | C8: =SUM(테마비교!P$3:P$2985) -> 24 | D8: =IF(B8=0,"",C8/B8) -> 0.00023182806 | E8: =COUNT(테마비교!O$3:O$2985) -> 1581
A9: 합계 | B9: =SUM(B5:B8) -> 1586288 | C9: =SUM(C5:C8) -> 513 | D9: =IF(B9=0,"",C9/B9) -> 0.00032339651
A11: 2) 같은 지면(태그×사이즈)에 4개 테마가 모두 노출된 경우만
A12: 테마 | B12: 노출수 | C12: 클릭수 | D12: 클릭률 | E12: 지면 수(태그×사이즈)
A13: whiteRedNo | B13: =SUMIFS(테마비교!F$3:F$2985,테마비교!$E$3:$E$2985,4) -> 562754 | C13: =SUMIFS(테마비교!G$3:G$2985,테마비교!$E$3:$E$2985,4) -> 162 | D13: =IF(B13=0,"",C13/B13) -> 0.00028787001 | E13: =COUNTIFS(테마비교!$E$3:$E$2985,4) -> 1358
A14: blackGoldNo | B14: =SUMIFS(테마비교!I$3:I$2985,테마비교!$E$3:$E$2985,4) -> 453941 | C14: =SUMIFS(테마비교!J$3:J$2985,테마비교!$E$3:$E$2985,4) -> 139 | D14: =IF(B14=0,"",C14/B14) -> 0.00030620719 | E14: =COUNTIFS(테마비교!$E$3:$E$2985,4) -> 1358
A15: magazine | B15: =SUMIFS(테마비교!L$3:L$2985,테마비교!$E$3:$E$2985,4) -> 453930 | C15: =SUMIFS(테마비교!M$3:M$2985,테마비교!$E$3:$E$2985,4) -> 184 | D15: =IF(B15=0,"",C15/B15) -> 0.00040534884 | E15: =COUNTIFS(테마비교!$E$3:$E$2985,4) -> 1358
A16: mcnal | B16: =SUMIFS(테마비교!O$3:O$2985,테마비교!$E$3:$E$2985,4) -> 102574 | C16: =SUMIFS(테마비교!P$3:P$2985,테마비교!$E$3:$E$2985,4) -> 24 | D16: =IF(B16=0,"",C16/B16) -> 0.00023397742 | E16: =COUNTIFS(테마비교!$E$3:$E$2985,4) -> 1358
A17: 합계 | B17: =SUM(B13:B16) -> 1573199 | C17: =SUM(C13:C16) -> 509 | D17: =IF(B17=0,"",C17/B17) -> 0.00032354457
A20: 메모
A21: · 원본: 1007.xlsx (2026-10-07). 같은 TAG ID + 사이즈를 한 행으로 묶고 테마별 노출수·클릭수를 옆으로 펼침.
A22: · 노출수·클릭수는 원본 값을 그대로 옮긴 것이고, 클릭률은 클릭수/노출수로 다시 계산(원본 H열은 % 단위 값).
A23: · 원본 I열(Y/N 구분)은 사용하지 않고 전 행을 집계함.
A24: · 노출이 몇 건뿐인 지면은 클릭 1건으로 클릭률이 크게 달라지므로 해석에 주의. 같은 지면끼리 비교하려면 2)번 표나 테마비교 시트의 "테마 수" 필터를 사용.
